Workbook
Name Slicer_City: #N/A

Sheet Raw Orders
A1: Order ID | B1: Customer ID | C1: Restaurant ID | D1: Restaurant Name | E1: City | F1: Order Date | G1: Delivery Date | H1: Delivery Time (min) | I1: Delivery Charge | J1: Delivery Partner | K1: Payment Mode
A2: ORD1001 | B2: U101 | C2: R001 | D2: Spice Hub | E2: Mumbai | F2: 01/09/2026 | G2: 02/09/2026 | H2: 35 | I2: 30 | J2: Assigned | K2: UPI
A3: ORD1002 | B3: U102 | C3: R002 | D3: Biryani House | E3: Delhi | F3: 02-09-2026 | G3: 03-09-2026 | H3: 42 | I3: 35 | K3: Card
A4: ORD1003 | B4: U103 | C4: R003 | D4: Pizza Corner | E4: Pune | F4: 03-Sep-2026 | G4: 04-Sep-2026 | H4: 38 | I4: 25 | J4: Rahul | K4: UPI
A5: ORD1004 | B5: U104 | C5: R004 | D5: South Treat | E5: Bengaluru | F5: 04/09/2026 | G5: 05/09/2026 | H5: 45 | I5: 40 | J5: Amit | K5: COD
A6: ORD1005 | B6: U105 | C6: R005 | D6: Tandoori Tales | E6: Ahmedabad | F6: 05-09-2026 | G6: 06-09-2026 | H6: 32 | I6: 30 | J6: Neeraj | K6: UPI
A7: ORD1006 | B7: U106 | C7: R006 | D7: Burger Point | E7: Mumbai | F7: 06/09/2026 | G7: 07/09/2026 | H7: 28 | I7: 20 | J7: Vikas | K7: Card
A8: ORD1007 | B8: U107 | C8: R007 | D8: Chaat Junction | E8: Delhi | F8: 07-09-2026 | G8: 08-09-2026 | H8: 36 | I8: 25 | K8: UPI
A9: ORD1008 | B9: U108 | C9: R008 | D9: Cafe Aroma | E9: Pune | F9: 08/09/2026 | G9: 09/09/2026 | H9: 41 | I9: 30 | J9: Sanjay | K9: Card
A10: ORD1009 | B10: U109 | C10: R009 | D10: Healthy Bites | E10: Bengaluru | F10: 09-Sep-2026 | G10: 10-Sep-2026 | H10: 33 | I10: 35 | J10: Ravi | K10: UPI
A11: ORD1010 | B11: U110 | C11: R010 | D11: Royal Thali | E11: Ahmedabad | F11: 10/09/2026 | G11: 11/09/2026 | H11: 50 | I11: 45 | J11: Karan | K11: COD
A12: ORD1011 | B12: U111 | C12: R001 | D12: Spice Hub | E12: Mumbai | F12: 11-09-2026 | G12: 12-09-2026 | H12: 31 | I12: 30 | J12: Rahul | K12: UPI
A13: ORD1012 | B13: U112 | C13: R002 | D13: Biryani House | E13: Delhi | F13: 12/09/2026 | G13: 13/09/2026 | H13: 47 | I13: 40 | K13: Card
A14: ORD1013 | B14: U113 | C14: R003 | D14: Pizza Corner | E14: Pune | F14: 13-Sep-2026 | G14: 14-Sep-2026 | H14: 39 | I14: 25 | J14: Amit | K14: UPI
A15: ORD1014 | B15: U114 | C15: R004 | D15: South Treat | E15: Bengaluru | F15: 14/09/2026 | G15: 15/09/2026 | H15: 44 | I15: 35 | J15: Neeraj | K15: COD
A16: ORD1015 | B16: U115 | C16: R005 | D16: Tandoori Tales | E16: Ahmedabad | F16: 15-09-2026 | G16: 16-09-2026 | H16: 37 | I16: 30 | J16: Vikas | K16: UPI
A17: ORD1016 | B17: U116 | C17: R006 | D17: Burger Point | E17: Mumbai | F17: 16/09/2026 | G17: 17/09/2026 | H17: 29 | I17: 20 | J17: Sanjay | K17: Card
A18: ORD1017 | B18: U117 | C18: R007 | D18: Chaat Junction | E18: Delhi | F18: 17-Sep-2026 | G18: 18-Sep-2026 | H18: 43 | I18: 25 | K18: UPI
A19: ORD1018 | B19: U118 | C19: R008 | D19: Cafe Aroma | E19: Pune | F19: 18/09/2026 | G19: 19/09/2026 | H19: 34 | I19: 30 | J19: Ravi | K19: Card
A20: ORD1019 | B20: U119 | C20: R009 | D20: Healthy Bites | E20: Bengaluru | F20: 19-09-2026 | G20: 20-09-2026 | H20: 48 | I20: 35 | J20: Karan | K20: UPI
A21: ORD1020 | B21: U120 | C21: R010 | D21: Royal Thali | E21: Ahmedabad | F21: 20/09/2026 | G21: 21/09/2026 | H21: 40 | I21: 45 | J21: Rahul | K21: COD
A22: ORD1021 | B22: U121 | C22: R001 | D22: Spice Hub | E22: Mumbai | F22: 21-Sep-2026 | G22: 22-Sep-2026 | H22: 36 | I22: 30 | J22: Amit | K22: UPI
A23: ORD1022 | B23: U122 | C23: R002 | D23: Biryani House | E23: Delhi | F23: 22/09/2026 | G23: 23/09/2026 | H23: 52 | I23: 40 | J23: Neeraj | K23: Card
A24: ORD1023 | B24: U123 | C24: R003 | D24: Pizza Corner | E24: Pune | F24: 23-09-2026 | G24: 24-09-2026 | H24: 30 | I24: 25 | J24: Vikas | K24: UPI
A25: ORD1024 | B25: U124 | C25: R004 | D25: South Treat | E25: Bengaluru | F25: 24/Sep/2026 | G25: 25/Sep/2026 | H25: 46 | I25: 35 | J25: Sanjay | K25: COD
A26: ORD1025 | B26: U125 | C26: R005 | D26: Tandoori Tales | E26: Ahmedabad | F26: 25/09/2026 | G26: 26/09/2026 | H26: 35 | I26: 30 | K26: UPI
A27: ORD1026 | B27: U126 | C27: R006 | D27: Burger Point | E27: Mumbai | F27: 26-09-2026 | G27: 27-09-2026 | H27: 27 | I27: 20 | J27: Ravi | K27: Card
A28: ORD1027 | B28: U127 | C28: R007 | D28: Chaat Junction | E28: Delhi | F28: 27/09/2026 | G28: 28/09/2026 | H28: 49 | I28: 25 | J28: Karan | K28: UPI
A29: ORD1028 | B29: U128 | C29: R008 | D29: Cafe Aroma | E29: Pune | F29: 28-Sep-2026 | G29: 29-Sep-2026 | H29: 37 | I29: 30 | J29: Rahul | K29: Card
A30: ORD1029 | B30: U129 | C30: R009 | D30: Healthy Bites | E30: Bengaluru | F30: 29/09/2026 | G30: 30/09/2026 | H30: 42 | I30: 35 | J30: Amit | K30: UPI
A31: ORD1030 | B31: U130 | C31: R010 | D31: Royal Thali | E31: Ahmedabad | F31: 30-09-2026 | G31: 01-10-2026 | H31: 55 | I31: 45 | J31: Neeraj | K31: COD
A32: ORD1031 | B32: U131 | C32: R001 | D32: Spice Hub | E32: Mumbai | F32: 01/10/2026 | G32: 02/10/2026 | H32: 33 | I32: 30 | J32: Vikas | K32: UPI
A33: ORD1032 | B33: U132 | C33: R002 | D33: Biryani House | E33: Delhi | F33: 02-Oct-2026 | G33: 03-Oct-2026 | H33: 45 | I33: 40 | K33: Card
A34: ORD1033 | B34: U133 | C34: R003 | D34: Pizza Corner | E34: Pune | F34: 03/10/2026 | G34: 04/10/2026 | H34: 41 | I34: 25 | J34: Sanjay | K34: UPI
A35: ORD1034 | B35: U134 | C35: R004 | D35: South Treat | E35: Bengaluru | F35: 04-10-2026 | G35: 05-10-2026 | H35: 39 | I35: 35 | J35: Ravi | K35: COD
A36: ORD1035 | B36: U135 | C36: R005 | D36: Tandoori Tales | E36: Ahmedabad | F36: 05/10/2026 | G36: 06/10/2026 | H36: 51 | I36: 30 | J36: Karan | K36: UPI
A37: ORD1036 | B37: U136 | C37: R006 | D37: Burger Point | E37: Mumbai | F37: 06-Oct-2026 | G37: 07-Oct-2026 | H37: 30 | I37: 20 | J37: Rahul | K37: Card
A38: ORD1037 | B38: U137 | C38: R007 | D38: Chaat Junction | E38: Delhi | F38: 07/10/2026 | G38: 08/10/2026 | H38: 44 | I38: 25 | K38: UPI
A39: ORD1038 | B39: U138 | C39: R008 | D39: Cafe Aroma | E39: Pune | F39: 08-10-2026 | G39: 09-10-2026 | H39: 35 | I39: 30 | J39: Amit | K39: Card
A40: ORD1039 | B40: U139 | C40: R009 | D40: Healthy Bites | E40: Bengaluru | F40: 09/10/2026 | G40: 10/10/2026 | H40: 47 | I40: 35 | J40: Neeraj | K40: UPI
...

Sheet Restaurant Details
A1: Restaurant ID | B1: Restaurant Name | C1: Cuisine | D1: Restaurant City
A2: R001 | B2: Spice Hub | C2: Indian | D2: Mumbai
A3: R002 | B3: Biryani House | C3: Biryani | D3: Delhi
A4: R003 | B4: Pizza Corner | C4: Pizza | D4: Pune
A5: R004 | B5: South Treat | C5: South Indian | D5: Bengaluru
A6: R005 | B6: Tandoori Tales | C6: North Indian | D6: Ahmedabad
A7: R006 | B7: Burger Point | C7: Fast Food | D7: Mumbai
A8: R007 | B8: Chaat Junction | C8: Street Food | D8: Delhi
A9: R008 | B9: Cafe Aroma | C9: Cafe | D9: Pune
A10: R009 | B10: Healthy Bites | C10: Healthy Food | D10: Bengaluru
A11: R010 | B11: Royal Thali | C11: Indian | D11: Ahmedabad

Sheet Tasks - 1,2,3
A1: Order ID | B1: Customer ID | C1: Restaurant ID | D1: Restaurant Name | E1: Cuisine | F1: City | G1: Order Date | H1: Delivery Date | I1: Delivery Time (min) | J1: Delivery Charge | K1: Delivery Partner | L1: Payment Mode | M1: Days
A2: ORD1001 | B2: U101 | C2: R001 | D2: =VLOOKUP(C2,'Restaurant Details'!$A$1:$D$11,MATCH($D$1,'Restaurant Details'!$A$1:$D$1,0),FALSE) -> Spice Hub | E2: =VLOOKUP(C2,'Restaurant Details'!$A$1:$D$11,MATCH($E$1,'Restaurant Details'!$A$1:$D$1,0),FALSE) -> Indian | F2: Mumbai | G2: 01/09/2026 | H2: 02/09/2026 | I2: 35 | J2: 30 | K2: Assigned | L2: UPI | M2: =TEXT(H2,"dddd") -> Wednesday
A3: ORD1002 | B3: U102 | C3: R002 | D3: =VLOOKUP(C3,'Restaurant Details'!$A$1:$D$11,MATCH($D$1,'Restaurant Details'!$A$1:$D$1,0),FALSE) -> Biryani House | E3: =VLOOKUP(C3,'Restaurant Details'!$A$1:$D$11,MATCH($E$1,'Restaurant Details'!$A$1:$D$1,0),FALSE) -> Biryani | F3: Delhi | G3: 02-09-2026 | H3: 03-09-2026 | I3: 42 | J3: 35 | K3: Unassigned | L3: Card | M3: =TEXT(H3,"dddd") -> Thursday
A4: ORD1003 | B4: U103 | C4: R003 | D4: =VLOOKUP(C4,'Restaurant Details'!$A$1:$D$11,MATCH($D$1,'Restaurant Details'!$A$1:$D$1,0),FALSE) -> Pizza Corner | E4: =VLOOKUP(C4,'Restaurant Details'!$A$1:$D$11,MATCH($E$1,'Restaurant Details'!$A$1:$D$1,0),FALSE) -> Pizza | F4: Pune | G4: 03-Sep-2026 | H4: 04-Sep-2026 | I4: 38 | J4: 25 | K4: Rahul | L4: UPI | M4: =TEXT(H4,"dddd") -> Friday
A5: ORD1004 | B5: U104 | C5: R004 | D5: =VLOOKUP(C5,'Restaurant Details'!$A$1:$D$11,MATCH($D$1,'Restaurant Details'!$A$1:$D$1,0),FALSE) -> South Treat | E5: =VLOOKUP(C5,'Restaurant Details'!$A$1:$D$11,MATCH($E$1,'Restaurant Details'!$A$1:$D$1,0),FALSE) -> South Indian | F5: Bengaluru | G5: 04/09/2026 | H5: 05/09/2026 | I5: 45 | J5: 40 | K5: Amit | L5: COD | M5: =TEXT(H5,"dddd") -> Saturday
A6: ORD1005 | B6: U105 | C6: R010 | D6: =VLOOKUP(C6,'Restaurant Details'!$A$1:$D$11,MATCH($D$1,'Restaurant Details'!$A$1:$D$1,0),FALSE) -> Royal Thali | E6: =VLOOKUP(C6,'Restaurant Details'!$A$1:$D$11,MATCH($E$1,'Restaurant Details'!$A$1:$D$1,0),FALSE) -> Indian | F6: Ahmedabad | G6: 05-09-2026 | H6: 06-09-2026 | I6: 32 | J6: 30 | K6: Neeraj | L6: UPI | M6: =TEXT(H6,"dddd") -> Sunday
A7: ORD1006 | B7: U106 | C7: R010 | D7: =VLOOKUP(C7,'Restaurant Details'!$A$1:$D$11,MATCH($D$1,'Restaurant Details'!$A$1:$D$1,0),FALSE) -> Royal Thali | E7: =VLOOKUP(C7,'Restaurant Details'!$A$1:$D$11,MATCH($E$1,'Restaurant Details'!$A$1:$D$1,0),FALSE) -> Indian | F7: Mumbai | G7: 06/09/2026 | H7: 07/09/2026 | I7: 28 | J7: 20 | K7: Vikas | L7: Card | M7: =TEXT(H7,"dddd") -> Monday
A8: ORD1007 | B8: U107 | C8: R007 | D8: =VLOOKUP(C8,'Restaurant Details'!$A$1:$D$11,MATCH($D$1,'Restaurant Details'!$A$1:$D$1,0),FALSE) -> Chaat Junction | E8: =VLOOKUP(C8,'Restaurant Details'!$A$1:$D$11,MATCH($E$1,'Restaurant Details'!$A$1:$D$1,0),FALSE) -> Street Food | F8: Delhi | G8: 07-09-2026 | H8: 08-09-2026 | I8: 36 | J8: 25 | K8: Unassigned | L8: UPI | M8: =TEXT(H8,"dddd") -> Tuesday
A9: ORD1008 | B9: U108 | C9: R008 | D9: =VLOOKUP(C9,'Restaurant Details'!$A$1:$D$11,MATCH($D$1,'Restaurant Details'!$A$1:$D$1,0),FALSE) -> Cafe Aroma | E9: =VLOOKUP(C9,'Restaurant Details'!$A$1:$D$11,MATCH($E$1,'Restaurant Details'!$A$1:$D$1,0),FALSE) -> Cafe | F9: Pune | G9: 08/09/2026 | H9: 09/09/2026 | I9: 41 | J9: 30 | K9: Sanjay | L9: Card | M9: =TEXT(H9,"dddd") -> Wednesday
A10: ORD1009 | B10: U109 | C10: R009 | D10: =VLOOKUP(C10,'Restaurant Details'!$A$1:$D$11,MATCH($D$1,'Restaurant Details'!$A$1:$D$1,0),FALSE) -> Healthy Bites | E10: =VLOOKUP(C10,'Restaurant Details'!$A$1:$D$11,MATCH($E$1,'Restaurant Details'!$A$1:$D$1,0),FALSE) -> Healthy Food | F10: Bengaluru | G10: 09-Sep-2026 | H10: 10-Sep-2026 | I10: 33 | J10: 35 | K10: Ravi | L10: UPI | M10: =TEXT(H10,"dddd") -> Thursday
A11: ORD1010 | B11: U110 | C11: R010 | D11: =VLOOKUP(C11,'Restaurant Details'!$A$1:$D$11,MATCH($D$1,'Restaurant Details'!$A$1:$D$1,0),FALSE) -> Royal Thali | E11: =VLOOKUP(C11,'Restaurant Details'!$A$1:$D$11,MATCH($E$1,'Restaurant Details'!$A$1:$D$1,0),FALSE) -> Indian | F11: Ahmedabad | G11: 10/09/2026 | H11: 11/09/2026 | I11: 50 | J11: 45 | K11: Karan | L11: COD | M11: =TEXT(H11,"dddd") -> Friday
A12: ORD1011 | B12: U111 | C12: R009 | D12: =VLOOKUP(C12,'Restaurant Details'!$A$1:$D$11,MATCH($D$1,'Restaurant Details'!$A$1:$D$1,0),FALSE) -> Healthy Bites | E12: =VLOOKUP(C12,'Restaurant Details'!$A$1:$D$11,MATCH($E$1,'Restaurant Details'!$A$1:$D$1,0),FALSE) -> Healthy Food | F12: Mumbai | G12: 11-09-2026 | H12: 12-09-2026 | I12: 31 | J12: 30 | K12: Rahul | L12: UPI | M12: =TEXT(H12,"dddd") -> Saturday
A13: ORD1012 | B13: U112 | C13: R009 | D13: =VLOOKUP(C13,'Restaurant Details'!$A$1:$D$11,MATCH($D$1,'Restaurant Details'!$A$1:$D$1,0),FALSE) -> Healthy Bites | E13: =VLOOKUP(C13,'Restaurant Details'!$A$1:$D$11,MATCH($E$1,'Restaurant Details'!$A$1:$D$1,0),FALSE) -> Healthy Food | F13: Delhi | G13: 12/09/2026 | H13: 13/09/2026 | I13: 47 | J13: 40 | K13: Unassigned | L13: Card | M13: =TEXT(H13,"dddd") -> Sunday
... A49: ORD1048 | B49: U148 | C49: R008 | D49: =VLOOKUP(C49,'Restaurant Details'!$A$1:$D$11,MATCH($D$1,'Restaurant Details'!$A$1:$D$1,0),FALSE) -> Cafe Aroma | E49: =VLOOKUP(C49,'Restaurant Details'!$A$1:$D$11,MATCH($E$1,'Restaurant Details'!$A$1:$D$1,0),FALSE) -> Cafe | F49: Pune | G49: 18/10/2026 | H49: 19/10/2026 | I49: 32 | J49: 30 | K49: Vikas | L49: Card | M49: =TEXT(H49,"dddd") -> Monday

Sheet Task 4
A3: Row Labels | B3: Sum of Delivery Charge | C3: Count of Order ID
A4: Ahmedabad | B4: 330 | C4: 9
A5: Bengaluru | B5: 320 | C5: 9
A6: Delhi | B6: 320 | C6: 10
A7: Mumbai | B7: 250 | C7: 10
A8: Pune | B8: 275 | C8: 10
A9: Grand Total | B9: 1495 | C9: 48

Sheet Task 5
A3: Count of Order ID | B3: Average of Delivery Time (min) | H3: Order DashBoard
A4: 48 | B4: 39.541667
H5: Total Order | M5: Avg Delivery Time
H6: =GETPIVOTDATA("Count of Order ID",$A$3) -> 48 | M6: =GETPIVOTDATA("Average of Delivery Time (min)",$A$3) -> 39.541667
A7: Row Labels | B7: Count of Order ID | D7: Restaurant Name | E7: Top 3 order
A8: Biryani House | B8: 4 | D8: {=INDEX(_xlfn._xlws.SORT(A8:B17,2,-1),_xlfn.SEQUENCE(3),{1,2})} -> South Treat | E8: 8
A9: Burger Point | B9: 3 | D9: Healthy Bites | E9: 7
A10: Cafe Aroma | B10: 5 | D10: Royal Thali | E10: 6
A11: Chaat Junction | B11: 4
A12: Healthy Bites | B12: 7
A13: Pizza Corner | B13: 4
A14: Royal Thali | B14: 6
A15: South Treat | B15: 8
A16: Spice Hub | B16: 4
A17: Tandoori Tales | B17: 3
A18: Grand Total | B18: 48
